Workbook

Sheet BaseTest
A1: Type | B1: Compliance | C1: Principle Code | D1: Guideline Code | E1: Success Criteria Code | F1: Specific Reference | G1: Researcher | H1: Resource
A2: error | B2: AA | C2: 2 | D2: 2.4 | E2: 2.4.2 | F2: H25 | G2: P1 | H2: Beging Section
A3: error | B3: AA | C3: 1 | D3: 1.4 | E3: 1.4.3 | F3: G18 | G3: P1 | H3: Beging Section
A4: error | B4: AA | C4: 2 | D4: 2.4 | E4: 2.4.2 | F4: H25 | G4: P1 | H4: Considerations Section
A5: error | B5: AA | C5: 1 | D5: 1.4 | E5: 1.4.3 | F5: G18 | G5: P1 | H5: Considerations Section
A6: error | B6: AA | C6: 4 | D6: 4.1 | E6: 4.1.2 | F6: H91 | G6: P1 | H6: Considerations Section
A7: error | B7: AA | C7: 1 | D7: 1.3 | E7: 1.3.1 | F7: F68 | G7: P1 | H7: Considerations Section
A8: error | B8: AA | C8: 2 | D8: 2.4 | E8: 2.4.2 | F8: H25 | G8: P1 | H8: Considerations Section
A9: error | B9: AA | C9: 1 | D9: 1.4 | E9: 1.4.3 | F9: G18 | G9: P1 | H9: Considerations Section
A10: error | B10: AA | C10: 2 | D10: 2.4 | E10: 2.4.2 | F10: H25 | G10: P1 | H10: Personas Section
A11: error | B11: AA | C11: 1 | D11: 1.4 | E11: 1.4.3 | F11: G18 | G11: P1 | H11: Personas Section
A12: error | B12: AA | C12: 2 | D12: 2.4 | E12: 2.4.2 | F12: H25 | G12: P1 | H12: Quiz Section
A13: error | B13: AA | C13: 1 | D13: 1.4 | E13: 1.4.3 | F13: G18 | G13: P1 | H13: Quiz Section
... A72: error | B72: AA | C72: 2 | D72: 2.4 | E72: 2.4.1 | F72: H64 | G72: P2 | H72: About Section

Sheet BaseWcag
A1: Layer WCAG Code | B1: Layer WCAG Description
A2: 1 | B2: Perceivable
A3: 1.1 | B3: Text Alternatives
A4: 1.1.1 | B4: Non-text Content
A5: 1.2 | B5: Time-based Media
A6: 1.2.1 | B6: Audio-only and Video-only (Prerecorded)
A7: 1.2.2 | B7: Captions (Prerecorded)
A8: 1.2.3 | B8: Audio Description or Media Alternative (Prerecorded)
A9: 1.2.4 | B9: Captions (Live)
A10: 1.2.5 | B10: Audio Description (Prerecorded)
A11: 1.2.6 | B11: Sign Language (Prerecorded)
A12: 1.2.7 | B12: Extended Audio Description (Prerecorded)
A13: 1.2.8 | B13: Media Alternative (Prerecorded)
A14: 1.2.9 | B14: Audio-only (Live)
... A35: 1.4.13 | B35: Content on Hover or Focus
A36: 2 | B36: Operable
A37: 2.1 | B37: Keyboard Accessible
A38: 2.1.1 | B38: Keyboard
A39: 2.1.2 | B39: No Keyboard Trap
A40: 2.1.3 | B40: Keyboard (No Exception)
A41: 2.1.4 | B41: Character Key Shortcuts
A42: 2.2 | B42: Enough Time
A43: 2.2.1 | B43: Timing Adjustable
A44: 2.2.2 | B44: Pause, Stop, Hide
A45: 2.2.3 | B45: No Timing
A46: 2.2.4 | B46: Interruptions
A47: 2.2.5 | B47: Re-authenticating
A48: 2.2.6 | B48: Timeouts
... A70: 2.5.6 | B70: Concurrent Input Mechanisms
A71: 3 | B71: Understandable
A72: 3.1 | B72: Readable
A73: 3.1.1 | B73: Language of Page
A74: 3.1.2 | B74: Language of Parts
A75: 3.1.3 | B75: Unusual Words
A76: 3.1.4 | B76: Abbreviations
A77: 3.1.5 | B77: Reading Level
A78: 3.1.6 | B78: Pronunciation
A79: 3.2 | B79: Predictable
A80: 3.2.1 | B80: On Focus
A81: 3.2.2 | B81: On Input
...

Sheet GeneralResults
A1: Researcher | B1: Compliance | C1: Principle Description | D1: Guideline Description | E1: Success Criteria Code | F1: Success Criteria Description
A2: =BaseTest!G17 -> P2 | B2: =BaseTest!B17 -> AA | C2: =VLOOKUP(BaseTest!C17,BaseWcag!$A$1:$B$10000,2,TRUE) -> Operable | D2: =VLOOKUP(BaseTest!D17,BaseWcag!$A$1:$B$10000,2,TRUE) -> Navigable | E2: =BaseTest!E17 -> 2.4.2 | F2: =VLOOKUP(E2,BaseWcag!$A$1:$B$10000,2,TRUE) -> Page Titled
A3: =BaseTest!G18 -> P2 | B3: =BaseTest!B18 -> AA | C3: =VLOOKUP(BaseTest!C18,BaseWcag!$A$1:$B$10000,2,TRUE) -> Perceivable | D3: =VLOOKUP(BaseTest!D18,BaseWcag!$A$1:$B$10000,2,TRUE) -> Distinguishable | E3: =BaseTest!E18 -> 1.4.3 | F3: =VLOOKUP(E3,BaseWcag!$A$1:$B$10000,2,TRUE) -> Contrast (Minimum)
A4: =BaseTest!G19 -> P2 | B4: =BaseTest!B19 -> AA | C4: =VLOOKUP(BaseTest!C19,BaseWcag!$A$1:$B$10000,2,TRUE) -> Perceivable | D4: =VLOOKUP(BaseTest!D19,BaseWcag!$A$1:$B$10000,2,TRUE) -> Distinguishable | E4: =BaseTest!E19 -> 1.4.3 | F4: =VLOOKUP(E4,BaseWcag!$A$1:$B$10000,2,TRUE) -> Contrast (Minimum)
A5: =BaseTest!G20 -> P2 | B5: =BaseTest!B20 -> AA | C5: =VLOOKUP(BaseTest!C20,BaseWcag!$A$1:$B$10000,2,TRUE) -> Operable | D5: =VLOOKUP(BaseTest!D20,BaseWcag!$A$1:$B$10000,2,TRUE) -> Navigable | E5: =BaseTest!E20 -> 2.4.2 | F5: =VLOOKUP(E5,BaseWcag!$A$1:$B$10000,2,TRUE) -> Page Titled
A6: =BaseTest!G21 -> P2 | B6: =BaseTest!B21 -> AA | C6: =VLOOKUP(BaseTest!C21,BaseWcag!$A$1:$B$10000,2,TRUE) -> Perceivable | D6: =VLOOKUP(BaseTest!D21,BaseWcag!$A$1:$B$10000,2,TRUE) -> Distinguishable | E6: =BaseTest!E21 -> 1.4.3 | F6: =VLOOKUP(E6,BaseWcag!$A$1:$B$10000,2,TRUE) -> Contrast (Minimum)
A7: =BaseTest!G22 -> P2 | B7: =BaseTest!B22 -> AA | C7: =VLOOKUP(BaseTest!C22,BaseWcag!$A$1:$B$10000,2,TRUE) -> Perceivable | D7: =VLOOKUP(BaseTest!D22,BaseWcag!$A$1:$B$10000,2,TRUE) -> Distinguishable | E7: =BaseTest!E22 -> 1.4.3 | F7: =VLOOKUP(E7,BaseWcag!$A$1:$B$10000,2,TRUE) -> Contrast (Minimum)
A8: =BaseTest!G23 -> P2 | B8: =BaseTest!B23 -> AA | C8: =VLOOKUP(BaseTest!C23,BaseWcag!$A$1:$B$10000,2,TRUE) -> Robust | D8: =VLOOKUP(BaseTest!D23,BaseWcag!$A$1:$B$10000,2,TRUE) -> Compatible | E8: =BaseTest!E23 -> 4.1.2 | F8: =VLOOKUP(E8,BaseWcag!$A$1:$B$10000,2,TRUE) -> Name, Role, Value
A9: =BaseTest!G24 -> P2 | B9: =BaseTest!B24 -> AA | C9: =VLOOKUP(BaseTest!C24,BaseWcag!$A$1:$B$10000,2,TRUE) -> Perceivable | D9: =VLOOKUP(BaseTest!D24,BaseWcag!$A$1:$B$10000,2,TRUE) -> Adaptable | E9: =BaseTest!E24 -> 1.3.1 | F9: =VLOOKUP(E9,BaseWcag!$A$1:$B$10000,2,TRUE) -> Info and Relationships
A10: =BaseTest!G25 -> P2 | B10: =BaseTest!B25 -> AA | C10: =VLOOKUP(BaseTest!C25,BaseWcag!$A$1:$B$10000,2,TRUE) -> Perceivable | D10: =VLOOKUP(BaseTest!D25,BaseWcag!$A$1:$B$10000,2,TRUE) -> Distinguishable | E10: =BaseTest!E25 -> 1.4.3 | F10: =VLOOKUP(E10,BaseWcag!$A$1:$B$10000,2,TRUE) -> Contrast (Minimum)
A11: =BaseTest!G26 -> P2 | B11: =BaseTest!B26 -> AA | C11: =VLOOKUP(BaseTest!C26,BaseWcag!$A$1:$B$10000,2,TRUE) -> Perceivable | D11: =VLOOKUP(BaseTest!D26,BaseWcag!$A$1:$B$10000,2,TRUE) -> Distinguishable | E11: =BaseTest!E26 -> 1.4.3 | F11: =VLOOKUP(E11,BaseWcag!$A$1:$B$10000,2,TRUE) -> Contrast (Minimum)
A12: =BaseTest!G27 -> P2 | B12: =BaseTest!B27 -> AA | C12: =VLOOKUP(BaseTest!C27,BaseWcag!$A$1:$B$10000,2,TRUE) -> Perceivable | D12: =VLOOKUP(BaseTest!D27,BaseWcag!$A$1:$B$10000,2,TRUE) -> Distinguishable | E12: =BaseTest!E27 -> 1.4.3 | F12: =VLOOKUP(E12,BaseWcag!$A$1:$B$10000,2,TRUE) -> Contrast (Minimum)
A13: =BaseTest!G28 -> P2 | B13: =BaseTest!B28 -> AA | C13: =VLOOKUP(BaseTest!C28,BaseWcag!$A$1:$B$10000,2,TRUE) -> Perceivable | D13: =VLOOKUP(BaseTest!D28,BaseWcag!$A$1:$B$10000,2,TRUE) -> Distinguishable | E13: =BaseTest!E28 -> 1.4.3 | F13: =VLOOKUP(E13,BaseWcag!$A$1:$B$10000,2,TRUE) -> Contrast (Minimum)
... A39: =BaseTest!G54 -> P2 | B39: =BaseTest!B54 -> AA | C39: =VLOOKUP(BaseTest!C54,BaseWcag!$A$1:$B$10000,2,TRUE) -> Perceivable | D39: =VLOOKUP(BaseTest!D54,BaseWcag!$A$1:$B$10000,2,TRUE) -> Adaptable | E39: =BaseTest!E54 -> 1.3.1 | F39: =VLOOKUP(E39,BaseWcag!$A$1:$B$10000,2,TRUE) -> Info and Relationships
A40: =BaseTest!G62 -> P2 | B40: =BaseTest!B62 -> AA | C40: =VLOOKUP(BaseTest!C62,BaseWcag!$A$1:$B$10000,2,TRUE) -> Robust | D40: =VLOOKUP(BaseTest!D62,BaseWcag!$A$1:$B$10000,2,TRUE) -> Compatible | E40: =BaseTest!E62 -> 4.1.2 | F40: =VLOOKUP(E40,BaseWcag!$A$1:$B$10000,2,TRUE) -> Name, Role, Value
A41: =BaseTest!G63 -> P2 | B41: =BaseTest!B63 -> AA | C41: =VLOOKUP(BaseTest!C63,BaseWcag!$A$1:$B$10000,2,TRUE) -> Perceivable | D41: =VLOOKUP(BaseTest!D63,BaseWcag!$A$1:$B$10000,2,TRUE) -> Adaptable | E41: =BaseTest!E63 -> 1.3.1 | F41: =VLOOKUP(E41,BaseWcag!$A$1:$B$10000,2,TRUE) -> Info and Relationships
A42: =BaseTest!G64 -> P2 | B42: =BaseTest!B64 -> AA | C42: =VLOOKUP(BaseTest!C64,BaseWcag!$A$1:$B$10000,2,TRUE) -> Robust | D42: =VLOOKUP(BaseTest!D64,BaseWcag!$A$1:$B$10000,2,TRUE) -> Compatible | E42: =BaseTest!E64 -> 4.1.2 | F42: =VLOOKUP(E42,BaseWcag!$A$1:$B$10000,2,TRUE) -> Name, Role, Value
A43: =BaseTest!G65 -> P2 | B43: =BaseTest!B65 -> AA | C43: =VLOOKUP(BaseTest!C65,BaseWcag!$A$1:$B$10000,2,TRUE) -> Perceivable | D43: =VLOOKUP(BaseTest!D65,BaseWcag!$A$1:$B$10000,2,TRUE) -> Adaptable | E43: =BaseTest!E65 -> 1.3.1 | F43: =VLOOKUP(E43,BaseWcag!$A$1:$B$10000,2,TRUE) -> Info and Relationships
A44: =BaseTest!G66 -> P2 | B44: =BaseTest!B66 -> AA | C44: =VLOOKUP(BaseTest!C66,BaseWcag!$A$1:$B$10000,2,TRUE) -> Robust | D44: =VLOOKUP(BaseTest!D66,BaseWcag!$A$1:$B$10000,2,TRUE) -> Compatible | E44: =BaseTest!E66 -> 4.1.2 | F44: =VLOOKUP(E44,BaseWcag!$A$1:$B$10000,2,TRUE) -> Name, Role, Value
A45: =BaseTest!G67 -> P2 | B45: =BaseTest!B67 -> AA | C45: =VLOOKUP(BaseTest!C67,BaseWcag!$A$1:$B$10000,2,TRUE) -> Perceivable | D45: =VLOOKUP(BaseTest!D67,BaseWcag!$A$1:$B$10000,2,TRUE) -> Adaptable | E45: =BaseTest!E67 -> 1.3.1 | F45: =VLOOKUP(E45,BaseWcag!$A$1:$B$10000,2,TRUE) -> Info and Relationships
A46: =BaseTest!G68 -> P2 | B46: =BaseTest!B68 -> AA | C46: =VLOOKUP(BaseTest!C68,BaseWcag!$A$1:$B$10000,2,TRUE) -> Perceivable | D46: =VLOOKUP(BaseTest!D68,BaseWcag!$A$1:$B$10000,2,TRUE) -> Distinguishable | E46: =BaseTest!E68 -> 1.4.3 | F46: =VLOOKUP(E46,BaseWcag!$A$1:$B$10000,2,TRUE) -> Contrast (Minimum)
A47: =BaseTest!G5 -> P1 | B47: =BaseTest!B5 -> AA | C47: =VLOOKUP(BaseTest!C5,BaseWcag!$A$1:$B$10000,2,TRUE) -> Perceivable | D47: =VLOOKUP(BaseTest!D5,BaseWcag!$A$1:$B$10000,2,TRUE) -> Distinguishable | E47: =BaseTest!E5 -> 1.4.3 | F47: =VLOOKUP(E47,BaseWcag!$A$1:$B$10000,2,TRUE) -> Contrast (Minimum)
A48: =BaseTest!G6 -> P1 | B48: =BaseTest!B6 -> AA | C48: =VLOOKUP(BaseTest!C6,BaseWcag!$A$1:$B$10000,2,TRUE) -> Robust | D48: =VLOOKUP(BaseTest!D6,BaseWcag!$A$1:$B$10000,2,TRUE) -> Compatible | E48: =BaseTest!E6 -> 4.1.2 | F48: =VLOOKUP(E48,BaseWcag!$A$1:$B$10000,2,TRUE) -> Name, Role, Value
A49: =BaseTest!G7 -> P1 | B49: =BaseTest!B7 -> AA | C49: =VLOOKUP(BaseTest!C7,BaseWcag!$A$1:$B$10000,2,TRUE) -> Perceivable | D49: =VLOOKUP(BaseTest!D7,BaseWcag!$A$1:$B$10000,2,TRUE) -> Adaptable | E49: =BaseTest!E7 -> 1.3.1 | F49: =VLOOKUP(E49,BaseWcag!$A$1:$B$10000,2,TRUE) -> Info and Relationships
A50: =BaseTest!G8 -> P1 | B50: =BaseTest!B8 -> AA | C50: =VLOOKUP(BaseTest!C8,BaseWcag!$A$1:$B$10000,2,TRUE) -> Operable | D50: =VLOOKUP(BaseTest!D8,BaseWcag!$A$1:$B$10000,2,TRUE) -> Navigable | E50: =BaseTest!E8 -> 2.4.2 | F50: =VLOOKUP(E50,BaseWcag!$A$1:$B$10000,2,TRUE) -> Page Titled
A51: =BaseTest!G9 -> P1 | B51: =BaseTest!B9 -> AA | C51: =VLOOKUP(BaseTest!C9,BaseWcag!$A$1:$B$10000,2,TRUE) -> Perceivable | D51: =VLOOKUP(BaseTest!D9,BaseWcag!$A$1:$B$10000,2,TRUE) -> Distinguishable | E51: =BaseTest!E9 -> 1.4.3 | F51: =VLOOKUP(E51,BaseWcag!$A$1:$B$10000,2,TRUE) -> Contrast (Minimum)
A52: =BaseTest!G10 -> P1 | B52: =BaseTest!B10 -> AA | C52: =VLOOKUP(BaseTest!C10,BaseWcag!$A$1:$B$10000,2,TRUE) -> Operable | D52: =VLOOKUP(BaseTest!D10,BaseWcag!$A$1:$B$10000,2,TRUE) -> Navigable | E52: =BaseTest!E10 -> 2.4.2 | F52: =VLOOKUP(E52,BaseWcag!$A$1:$B$10000,2,TRUE) -> Page Titled
A53: =BaseTest!G11 -> P1 | B53: =BaseTest!B11 -> AA | C53: =VLOOKUP(BaseTest!C11,BaseWcag!$A$1:$B$10000,2,TRUE) -> Perceivable | D53: =VLOOKUP(BaseTest!D11,BaseWcag!$A$1:$B$10000,2,TRUE) -> Distinguishable | E53: =BaseTest!E11 -> 1.4.3 | F53: =VLOOKUP(E53,BaseWcag!$A$1:$B$10000,2,TRUE) -> Contrast (Minimum)
A54: =BaseTest!G12 -> P1 | B54: =BaseTest!B12 -> AA | C54: =VLOOKUP(BaseTest!C12,BaseWcag!$A$1:$B$10000,2,TRUE) -> Operable | D54: =VLOOKUP(BaseTest!D12,BaseWcag!$A$1:$B$10000,2,TRUE) -> Navigable | E54: =BaseTest!E12 -> 2.4.2 | F54: =VLOOKUP(E54,BaseWcag!$A$1:$B$10000,2,TRUE) -> Page Titled
A55: =BaseTest!G13 -> P1 | B55: =BaseTest!B13 -> AA | C55: =VLOOKUP(BaseTest!C13,BaseWcag!$A$1:$B$10000,2,TRUE) -> Perceivable | D55: =VLOOKUP(BaseTest!D13,BaseWcag!$A$1:$B$10000,2,TRUE) -> Distinguishable | E55: =BaseTest!E13 -> 1.4.3 | F55: =VLOOKUP(E55,BaseWcag!$A$1:$B$10000,2,TRUE) -> Contrast (Minimum)
A56: =BaseTest!G14 -> P1 | B56: =BaseTest!B14 -> AA | C56: =VLOOKUP(BaseTest!C14,BaseWcag!$A$1:$B$10000,2,TRUE) -> Operable | D56: =VLOOKUP(BaseTest!D14,BaseWcag!$A$1:$B$10000,2,TRUE) -> Navigable | E56: =BaseTest!E14 -> 2.4.2 | F56: =VLOOKUP(E56,BaseWcag!$A$1:$B$10000,2,TRUE) -> Page Titled
A57: =BaseTest!G15 -> P1 | B57: =BaseTest!B15 -> AA | C57: =VLOOKUP(BaseTest!C15,BaseWcag!$A$1:$B$10000,2,TRUE) -> Perceivable | D57: =VLOOKUP(BaseTest!D15,BaseWcag!$A$1:$B$10000,2,TRUE) -> Distinguishable | E57: =BaseTest!E15 -> 1.4.3 | F57: =VLOOKUP(E57,BaseWcag!$A$1:$B$10000,2,TRUE) -> Contrast (Minimum)
A58: =BaseTest!G16 -> P1 | B58: =BaseTest!B16 -> AA | C58: =VLOOKUP(BaseTest!C16,BaseWcag!$A$1:$B$10000,2,TRUE) -> Operable | D58: =VLOOKUP(BaseTest!D16,BaseWcag!$A$1:$B$10000,2,TRUE) -> Navigable | E58: =BaseTest!E16 -> 2.4.1 | F58: =VLOOKUP(E58,BaseWcag!$A$1:$B$10000,2,TRUE) -> Bypass Blocks
A59: =BaseTest!G55 -> P2 | B59: =BaseTest!B55 -> AA | C59: =VLOOKUP(BaseTest!C55,BaseWcag!$A$1:$B$10000,2,TRUE) -> Robust | D59: =VLOOKUP(BaseTest!D55,BaseWcag!$A$1:$B$10000,2,TRUE) -> Compatible | E59: =BaseTest!E55 -> 4.1.2 | F59: =VLOOKUP(E59,BaseWcag!$A$1:$B$10000,2,TRUE) -> Name, Role, Value
A60: =BaseTest!G56 -> P2 | B60: =BaseTest!B56 -> AA | C60: =VLOOKUP(BaseTest!C56,BaseWcag!$A$1:$B$10000,2,TRUE) -> Perceivable | D60: =VLOOKUP(BaseTest!D56,BaseWcag!$A$1:$B$10000,2,TRUE) -> Adaptable | E60: =BaseTest!E56 -> 1.3.1 | F60: =VLOOKUP(E60,BaseWcag!$A$1:$B$10000,2,TRUE) -> Info and Relationships
A61: =BaseTest!G57 -> P2 | B61: =BaseTest!B57 -> AA | C61: =VLOOKUP(BaseTest!C57,BaseWcag!$A$1:$B$10000,2,TRUE) -> Perceivable | D61: =VLOOKUP(BaseTest!D57,BaseWcag!$A$1:$B$10000,2,TRUE) -> Distinguishable | E61: =BaseTest!E57 -> 1.4.3 | F61: =VLOOKUP(E61,BaseWcag!$A$1:$B$10000,2,TRUE) -> Contrast (Minimum)
A62: =BaseTest!G58 -> P2 | B62: =BaseTest!B58 -> AA | C62: =VLOOKUP(BaseTest!C58,BaseWcag!$A$1:$B$10000,2,TRUE) -> Robust | D62: =VLOOKUP(BaseTest!D58,BaseWcag!$A$1:$B$10000,2,TRUE) -> Compatible | E62: =BaseTest!E58 -> 4.1.2 | F62: =VLOOKUP(E62,BaseWcag!$A$1:$B$10000,2,TRUE) -> Name, Role, Value
A63: =BaseTest!G59 -> P2 | B63: =BaseTest!B59 -> AA | C63: =VLOOKUP(BaseTest!C59,BaseWcag!$A$1:$B$10000,2,TRUE) -> Perceivable | D63: =VLOOKUP(BaseTest!D59,BaseWcag!$A$1:$B$10000,2,TRUE) -> Adaptable | E63: =BaseTest!E59 -> 1.3.1 | F63: =VLOOKUP(E63,BaseWcag!$A$1:$B$10000,2,TRUE) -> Info and Relationships
A64: =BaseTest!G60 -> P2 | B64: =BaseTest!B60 -> AA | C64: =VLOOKUP(BaseTest!C60,BaseWcag!$A$1:$B$10000,2,TRUE) -> Robust | D64: =VLOOKUP(BaseTest!D60,BaseWcag!$A$1:$B$10000,2,TRUE) -> Compatible | E64: =BaseTest!E60 -> 4.1.2 | F64: =VLOOKUP(E64,BaseWcag!$A$1:$B$10000,2,TRUE) -> Name, Role, Value
A65: =BaseTest!G61 -> P2 | B65: =BaseTest!B61 -> AA | C65: =VLOOKUP(BaseTest!C61,BaseWcag!$A$1:$B$10000,2,TRUE) -> Perceivable | D65: =VLOOKUP(BaseTest!D61,BaseWcag!$A$1:$B$10000,2,TRUE) -> Adaptable | E65: =BaseTest!E61 -> 1.3.1 | F65: =VLOOKUP(E65,BaseWcag!$A$1:$B$10000,2,TRUE) -> Info and Relationships
...

Sheet WCAGPrincipleResult
A1: Principle Description | B1: P1 | C1: P2
A2: Perceivable | B2: =COUNTIFS(GeneralResults!$C:$C,WCAGPrincipleResult!A2,GeneralResults!$A:$A,$B$1) -> 7 | C2: =COUNTIFS(GeneralResults!$C:$C,WCAGPrincipleResult!A2,GeneralResults!$A:$A,$C$1) -> 37
A3: Operable | B3: =COUNTIFS(GeneralResults!$C:$C,WCAGPrincipleResult!A3,GeneralResults!$A:$A,$B$1) -> 7 | C3: =COUNTIFS(GeneralResults!$C:$C,WCAGPrincipleResult!A3,GeneralResults!$A:$A,$C$1) -> 7
A4: Understandable | B4: =COUNTIFS(GeneralResults!$C:$C,WCAGPrincipleResult!A4,GeneralResults!$A:$A,$B$1) -> 0 | C4: =COUNTIFS(GeneralResults!$C:$C,WCAGPrincipleResult!A4,GeneralResults!$A:$A,$C$1) -> 0
A5: Robust | B5: =COUNTIFS(GeneralResults!$C:$C,WCAGPrincipleResult!A5,GeneralResults!$A:$A,$B$1) -> 1 | C5: =COUNTIFS(GeneralResults!$C:$C,WCAGPrincipleResult!A5,GeneralResults!$A:$A,$C$1) -> 12

Sheet WCAGGuidelineResult
A1: Principle Description | B1: Guideline Description | C1: P1 | D1: P2 | E1: Has Violation
A2: Perceivable | B2: Text Alternatives | C2: =IF(COUNTIFS(GeneralResults!$D:$D,WCAGGuidelineResult!B2,GeneralResults!$A:$A,$C$1)=0,"",COUNTIFS(GeneralResults!$D:$D,WCAGGuidelineResult!B2,GeneralResults!$A:$A,$C$1)) | D2: =IF(COUNTIFS(GeneralResults!$D:$D,WCAGGuidelineResult!B2,GeneralResults!$A:$A,$D$1)=0,"",COUNTIFS(GeneralResults!$D:$D,WCAGGuidelineResult!B2,GeneralResults!$A:$A,$D$1)) | E2: =IF(AND(C2="",D2=""),0,1) -> 0
A3: Perceivable | B3: Time-based Media | C3: =IF(COUNTIFS(GeneralResults!$D:$D,WCAGGuidelineResult!B3,GeneralResults!$A:$A,$C$1)=0,"",COUNTIFS(GeneralResults!$D:$D,WCAGGuidelineResult!B3,GeneralResults!$A:$A,$C$1)) | D3: =IF(COUNTIFS(GeneralResults!$D:$D,WCAGGuidelineResult!B3,GeneralResults!$A:$A,$D$1)=0,"",COUNTIFS(GeneralResults!$D:$D,WCAGGuidelineResult!B3,GeneralResults!$A:$A,$D$1)) | E3: =IF(AND(C3="",D3=""),0,1) -> 0
A4: Perceivable | B4: Adaptable | C4: =IF(COUNTIFS(GeneralResults!$D:$D,WCAGGuidelineResult!B4,GeneralResults!$A:$A,$C$1)=0,"",COUNTIFS(GeneralResults!$D:$D,WCAGGuidelineResult!B4,GeneralResults!$A:$A,$C$1)) -> 1 | D4: =IF(COUNTIFS(GeneralResults!$D:$D,WCAGGuidelineResult!B4,GeneralResults!$A:$A,$D$1)=0,"",COUNTIFS(GeneralResults!$D:$D,WCAGGuidelineResult!B4,GeneralResults!$A:$A,$D$1)) -> 11 | E4: =IF(AND(C4="",D4=""),0,1) -> 1
A5: Perceivable | B5: Distinguishable | C5: =IF(COUNTIFS(GeneralResults!$D:$D,WCAGGuidelineResult!B5,GeneralResults!$A:$A,$C$1)=0,"",COUNTIFS(GeneralResults!$D:$D,WCAGGuidelineResult!B5,GeneralResults!$A:$A,$C$1)) -> 6 | D5: =IF(COUNTIFS(GeneralResults!$D:$D,WCAGGuidelineResult!B5,GeneralResults!$A:$A,$D$1)=0,"",COUNTIFS(GeneralResults!$D:$D,WCAGGuidelineResult!B5,GeneralResults!$A:$A,$D$1)) -> 26 | E5: =IF(AND(C5="",D5=""),0,1) -> 1
A6: Operable | B6: Keyboard Accessible | C6: =IF(COUNTIFS(GeneralResults!$D:$D,WCAGGuidelineResult!B6,GeneralResults!$A:$A,$C$1)=0,"",COUNTIFS(GeneralResults!$D:$D,WCAGGuidelineResult!B6,GeneralResults!$A:$A,$C$1)) | D6: =IF(COUNTIFS(GeneralResults!$D:$D,WCAGGuidelineResult!B6,GeneralResults!$A:$A,$D$1)=0,"",COUNTIFS(GeneralResults!$D:$D,WCAGGuidelineResult!B6,GeneralResults!$A:$A,$D$1)) | E6: =IF(AND(C6="",D6=""),0,1) -> 0
A7: Operable | B7: Enough Time | C7: =IF(COUNTIFS(GeneralResults!$D:$D,WCAGGuidelineResult!B7,GeneralResults!$A:$A,$C$1)=0,"",COUNTIFS(GeneralResults!$D:$D,WCAGGuidelineResult!B7,GeneralResults!$A:$A,$C$1)) | D7: =IF(COUNTIFS(GeneralResults!$D:$D,WCAGGuidelineResult!B7,GeneralResults!$A:$A,$D$1)=0,"",COUNTIFS(GeneralResults!$D:$D,WCAGGuidelineResult!B7,GeneralResults!$A:$A,$D$1)) | E7: =IF(AND(C7="",D7=""),0,1) -> 0
A8: Operable | B8: Seizures and Physical Reactions | C8: =IF(COUNTIFS(GeneralResults!$D:$D,WCAGGuidelineResult!B8,GeneralResults!$A:$A,$C$1)=0,"",COUNTIFS(GeneralResults!$D:$D,WCAGGuidelineResult!B8,GeneralResults!$A:$A,$C$1)) | D8: =IF(COUNTIFS(GeneralResults!$D:$D,WCAGGuidelineResult!B8,GeneralResults!$A:$A,$D$1)=0,"",COUNTIFS(GeneralResults!$D:$D,WCAGGuidelineResult!B8,GeneralResults!$A:$A,$D$1)) | E8: =IF(AND(C8="",D8=""),0,1) -> 0
A9: Operable | B9: Navigable | C9: =IF(COUNTIFS(GeneralResults!$D:$D,WCAGGuidelineResult!B9,GeneralResults!$A:$A,$C$1)=0,"",COUNTIFS(GeneralResults!$D:$D,WCAGGuidelineResult!B9,GeneralResults!$A:$A,$C$1)) -> 7 | D9: =IF(COUNTIFS(GeneralResults!$D:$D,WCAGGuidelineResult!B9,GeneralResults!$A:$A,$D$1)=0,"",COUNTIFS(GeneralResults!$D:$D,WCAGGuidelineResult!B9,GeneralResults!$A:$A,$D$1)) -> 7 | E9: =IF(AND(C9="",D9=""),0,1) -> 1
A10: Operable | B10: Input Modalities | C10: =IF(COUNTIFS(GeneralResults!$D:$D,WCAGGuidelineResult!B10,GeneralResults!$A:$A,$C$1)=0,"",COUNTIFS(GeneralResults!$D:$D,WCAGGuidelineResult!B10,GeneralResults!$A:$A,$C$1)) | D10: =IF(COUNTIFS(GeneralResults!$D:$D,WCAGGuidelineResult!B10,GeneralResults!$A:$A,$D$1)=0,"",COUNTIFS(GeneralResults!$D:$D,WCAGGuidelineResult!B10,GeneralResults!$A:$A,$D$1)) | E10: =IF(AND(C10="",D10=""),0,1) -> 0
A11: Understandable | B11: Readable | C11: =IF(COUNTIFS(GeneralResults!$D:$D,WCAGGuidelineResult!B11,GeneralResults!$A:$A,$C$1)=0,"",COUNTIFS(GeneralResults!$D:$D,WCAGGuidelineResult!B11,GeneralResults!$A:$A,$C$1)) | D11: =IF(COUNTIFS(GeneralResults!$D:$D,WCAGGuidelineResult!B11,GeneralResults!$A:$A,$D$1)=0,"",COUNTIFS(GeneralResults!$D:$D,WCAGGuidelineResult!B11,GeneralResults!$A:$A,$D$1)) | E11: =IF(AND(C11="",D11=""),0,1) -> 0
A12: Understandable | B12: Predictable | C12: =IF(COUNTIFS(GeneralResults!$D:$D,WCAGGuidelineResult!B12,GeneralResults!$A:$A,$C$1)=0,"",COUNTIFS(GeneralResults!$D:$D,WCAGGuidelineResult!B12,GeneralResults!$A:$A,$C$1)) | D12: =IF(COUNTIFS(GeneralResults!$D:$D,WCAGGuidelineResult!B12,GeneralResults!$A:$A,$D$1)=0,"",COUNTIFS(GeneralResults!$D:$D,WCAGGuidelineResult!B12,GeneralResults!$A:$A,$D$1)) | E12: =IF(AND(C12="",D12=""),0,1) -> 0
A13: Understandable | B13: Input Assistance | C13: =IF(COUNTIFS(GeneralResults!$D:$D,WCAGGuidelineResult!B13,GeneralResults!$A:$A,$C$1)=0,"",COUNTIFS(GeneralResults!$D:$D,WCAGGuidelineResult!B13,GeneralResults!$A:$A,$C$1)) | D13: =IF(COUNTIFS(GeneralResults!$D:$D,WCAGGuidelineResult!B13,GeneralResults!$A:$A,$D$1)=0,"",COUNTIFS(GeneralResults!$D:$D,WCAGGuidelineResult!B13,GeneralResults!$A:$A,$D$1)) | E13: =IF(AND(C13="",D13=""),0,1) -> 0
A14: Robust | B14: Compatible | C14: =IF(COUNTIFS(GeneralResults!$D:$D,WCAGGuidelineResult!B14,GeneralResults!$A:$A,$C$1)=0,"",COUNTIFS(GeneralResults!$D:$D,WCAGGuidelineResult!B14,GeneralResults!$A:$A,$C$1)) -> 1 | D14: =IF(COUNTIFS(GeneralResults!$D:$D,WCAGGuidelineResult!B14,GeneralResults!$A:$A,$D$1)=0,"",COUNTIFS(GeneralResults!$D:$D,WCAGGuidelineResult!B14,GeneralResults!$A:$A,$D$1)) -> 12 | E14: =IF(AND(C14="",D14=""),0,1) -> 1

Sheet WCAGGuidelineResultDynamic
A1: Rótulos de Linha | B1: Soma de P1 | C1: Soma de P2
A2: Operable | B2: 7 | C2: 7
A3: Navigable | B3: 7 | C3: 7
A4: Perceivable | B4: 37 | C4: 7
A5: Adaptable | B5: 11 | C5: 1
A6: Distinguishable | B6: 26 | C6: 6
A7: Robust | B7: 12 | C7: 1
A8: Compatible | B8: 12 | C8: 1
A9: Total Geral | B9: 56 | C9: 15

Sheet WCAGSuccessCriteriaResult
A1: Guideline Code | B1: Guideline | C1: P1 | D1: P2 | E1: Has Violation
A2: 1.1.1 | B2: Non-text Content | C2: =IF(COUNTIFS(GeneralResults!$E:$E,A2,GeneralResults!$A:$A,$C$1)=0,"",COUNTIFS(GeneralResults!$E:$E,A2,GeneralResults!$A:$A,$C$1)) | D2: =IF(COUNTIFS(GeneralResults!$E:$E,A2,GeneralResults!$A:$A,$D$1)=0,"",COUNTIFS(GeneralResults!$E:$E,A2,GeneralResults!$A:$A,$D$1)) | E2: =IF(AND(C2="",D2=""),0,1) -> 0
A3: 1.2.1 | B3: Audio-only and Video-only (Prerecorded) | C3: =IF(COUNTIFS(GeneralResults!$E:$E,A3,GeneralResults!$A:$A,$C$1)=0,"",COUNTIFS(GeneralResults!$E:$E,A3,GeneralResults!$A:$A,$C$1)) | D3: =IF(COUNTIFS(GeneralResults!$E:$E,A3,GeneralResults!$A:$A,$D$1)=0,"",COUNTIFS(GeneralResults!$E:$E,A3,GeneralResults!$A:$A,$D$1)) | E3: =IF(AND(C3="",D3=""),0,1) -> 0
A4: 1.2.2 | B4: Captions (Prerecorded) | C4: =IF(COUNTIFS(GeneralResults!$E:$E,A4,GeneralResults!$A:$A,$C$1)=0,"",COUNTIFS(GeneralResults!$E:$E,A4,GeneralResults!$A:$A,$C$1)) | D4: =IF(COUNTIFS(GeneralResults!$E:$E,A4,GeneralResults!$A:$A,$D$1)=0,"",COUNTIFS(GeneralResults!$E:$E,A4,GeneralResults!$A:$A,$D$1)) | E4: =IF(AND(C4="",D4=""),0,1) -> 0
A5: 1.2.3 | B5: Audio Description or Media Alternative (Prerecorded) | C5: =IF(COUNTIFS(GeneralResults!$E:$E,A5,GeneralResults!$A:$A,$C$1)=0,"",COUNTIFS(GeneralResults!$E:$E,A5,GeneralResults!$A:$A,$C$1)) | D5: =IF(COUNTIFS(GeneralResults!$E:$E,A5,GeneralResults!$A:$A,$D$1)=0,"",COUNTIFS(GeneralResults!$E:$E,A5,GeneralResults!$A:$A,$D$1)) | E5: =IF(AND(C5="",D5=""),0,1) -> 0
A6: 1.2.4 | B6: Captions (Live) | C6: =IF(COUNTIFS(GeneralResults!$E:$E,A6,GeneralResults!$A:$A,$C$1)=0,"",COUNTIFS(GeneralResults!$E:$E,A6,GeneralResults!$A:$A,$C$1)) | D6: =IF(COUNTIFS(GeneralResults!$E:$E,A6,GeneralResults!$A:$A,$D$1)=0,"",COUNTIFS(GeneralResults!$E:$E,A6,GeneralResults!$A:$A,$D$1)) | E6: =IF(AND(C6="",D6=""),0,1) -> 0
A7: 1.2.5 | B7: Audio Description (Prerecorded) | C7: =IF(COUNTIFS(GeneralResults!$E:$E,A7,GeneralResults!$A:$A,$C$1)=0,"",COUNTIFS(GeneralResults!$E:$E,A7,GeneralResults!$A:$A,$C$1)) | D7: =IF(COUNTIFS(GeneralResults!$E:$E,A7,GeneralResults!$A:$A,$D$1)=0,"",COUNTIFS(GeneralResults!$E:$E,A7,GeneralResults!$A:$A,$D$1)) | E7: =IF(AND(C7="",D7=""),0,1) -> 0
A8: 1.2.6 | B8: Sign Language (Prerecorded) | C8: =IF(COUNTIFS(GeneralResults!$E:$E,A8,GeneralResults!$A:$A,$C$1)=0,"",COUNTIFS(GeneralResults!$E:$E,A8,GeneralResults!$A:$A,$C$1)) | D8: =IF(COUNTIFS(GeneralResults!$E:$E,A8,GeneralResults!$A:$A,$D$1)=0,"",COUNTIFS(GeneralResults!$E:$E,A8,GeneralResults!$A:$A,$D$1)) | E8: =IF(AND(C8="",D8=""),0,1) -> 0
A9: 1.2.7 | B9: Extended Audio Description (Prerecorded) | C9: =IF(COUNTIFS(GeneralResults!$E:$E,A9,GeneralResults!$A:$A,$C$1)=0,"",COUNTIFS(GeneralResults!$E:$E,A9,GeneralResults!$A:$A,$C$1)) | D9: =IF(COUNTIFS(GeneralResults!$E:$E,A9,GeneralResults!$A:$A,$D$1)=0,"",COUNTIFS(GeneralResults!$E:$E,A9,GeneralResults!$A:$A,$D$1)) | E9: =IF(AND(C9="",D9=""),0,1) -> 0
A10: 1.2.8 | B10: Media Alternative (Prerecorded) | C10: =IF(COUNTIFS(GeneralResults!$E:$E,A10,GeneralResults!$A:$A,$C$1)=0,"",COUNTIFS(GeneralResults!$E:$E,A10,GeneralResults!$A:$A,$C$1)) | D10: =IF(COUNTIFS(GeneralResults!$E:$E,A10,GeneralResults!$A:$A,$D$1)=0,"",COUNTIFS(GeneralResults!$E:$E,A10,GeneralResults!$A:$A,$D$1)) | E10: =IF(AND(C10="",D10=""),0,1) -> 0
A11: 1.2.9 | B11: Audio-only (Live) | C11: =IF(COUNTIFS(GeneralResults!$E:$E,A11,GeneralResults!$A:$A,$C$1)=0,"",COUNTIFS(GeneralResults!$E:$E,A11,GeneralResults!$A:$A,$C$1)) | D11: =IF(COUNTIFS(GeneralResults!$E:$E,A11,GeneralResults!$A:$A,$D$1)=0,"",COUNTIFS(GeneralResults!$E:$E,A11,GeneralResults!$A:$A,$D$1)) | E11: =IF(AND(C11="",D11=""),0,1) -> 0
A12: 1.3.1 | B12: Info and Relationships | C12: =IF(COUNTIFS(GeneralResults!$E:$E,A12,GeneralResults!$A:$A,$C$1)=0,"",COUNTIFS(GeneralResults!$E:$E,A12,GeneralResults!$A:$A,$C$1)) -> 1 | D12: =IF(COUNTIFS(GeneralResults!$E:$E,A12,GeneralResults!$A:$A,$D$1)=0,"",COUNTIFS(GeneralResults!$E:$E,A12,GeneralResults!$A:$A,$D$1)) -> 11 | E12: =IF(AND(C12="",D12=""),0,1) -> 1
A13: 1.3.2 | B13: Meaningful Sequence | C13: =IF(COUNTIFS(GeneralResults!$E:$E,A13,GeneralResults!$A:$A,$C$1)=0,"",COUNTIFS(GeneralResults!$E:$E,A13,GeneralResults!$A:$A,$C$1)) | D13: =IF(COUNTIFS(GeneralResults!$E:$E,A13,GeneralResults!$A:$A,$D$1)=0,"",COUNTIFS(GeneralResults!$E:$E,A13,GeneralResults!$A:$A,$D$1)) | E13: =IF(AND(C13="",D13=""),0,1) -> 0
... A79: 4.1.3 | B79: Status Messages | C79: =IF(COUNTIFS(GeneralResults!$E:$E,A79,GeneralResults!$A:$A,$C$1)=0,"",COUNTIFS(GeneralResults!$E:$E,A79,GeneralResults!$A:$A,$C$1)) | D79: =IF(COUNTIFS(GeneralResults!$E:$E,A79,GeneralResults!$A:$A,$D$1)=0,"",COUNTIFS(GeneralResults!$E:$E,A79,GeneralResults!$A:$A,$D$1)) | E79: =IF(AND(C79="",D79=""),0,1) -> 0
